<?xml version="1.0" ?>
<!-- =================================================================================== -->
<!-- |    This document was autogenerated by xacro from iai_kitchen_python.urdf.xacro  | -->
<!-- |    EDITING THIS FILE BY HAND IS NOT RECOMMENDED                                 | -->
<!-- =================================================================================== -->
<robot name="iai_kitchen">
  <!--- FIXME THIS should NOT be here -->
  <!--
      <link name="map">
      
      <sphere_inertia radius="0" mass="0"/>
      </link>
      <iai_drawer_60_14 name="drawer_1" parent="map">
      <origin rpy="0 0 0" xyz="0 0 1"/>
      </iai_drawer_60_14>
      
      <iai_drawer_80_14 name="drawer_2" parent="map">
      <origin rpy="0 0 0" xyz="0 0 2"/>
      </iai_drawer_80_14>
      
      <iai_drawer_60_29 name="drawer_3" parent="map">
      <origin rpy="0 0 0" xyz="0 0 3"/>
      </iai_drawer_60_29>
      
      <iai_drawer_80_29 name="drawer_4" parent="map">
      <origin rpy="0 0 0" xyz="0 0 4"/>
      </iai_drawer_80_29>
      
      <iai_drawer_100_29 name="drawer_5" parent="map">
      <origin rpy="0 0 0" xyz="0 0 5"/>
      </iai_drawer_100_29>
  -->
  <link name="room_link">
    <inertial>
      <origin rpy="0 0 0" xyz="0.0 0.0 0.0"/>
      <mass value="1"/>
      <inertia ixx="1" ixy="0.0" ixz="0.0" iyy="1" iyz="0.0" izz="1"/>
    </inertial>
  </link>
  <link name="world"/>
  <joint name="world_room_joint" type="fixed">
    <origin rpy="0 0 0" xyz="0.0 0.03 0 "/>
    <parent link="world"/>
    <child link="room_link"/>
  </joint>
  <link name="sink_area_footprint">
    <inertial>
      <origin rpy="0 0 0" xyz="0.0 0.0 0.0"/>
      <mass value="1"/>
      <inertia ixx="1" ixy="0.0" ixz="0.0" iyy="1" iyz="0.0" izz="1"/>
    </inertial>
  </link>
  <link name="sink_area">
    <inertial>
      <origin rpy="0 0 0" xyz="0.0 0.0 0.0"/>
      <mass value="1"/>
      <inertia ixx="1" ixy="0.0" ixz="0.0" iyy="1" iyz="0.0" izz="1"/>
    </inertial>
    <visual>
      <origin rpy="0 0 0" xyz="0 0 0"/>
      <geometry>
        <mesh filename="package://iai_kitchen/meshes/racks/SinkArea.dae"/>
      </geometry>
    </visual>
    <collision>
      <origin rpy="0 0 0" xyz="0 0 0"/>
      <geometry>
        <mesh filename="package://iai_kitchen/meshes/racks/SinkArea.obj"/>
      </geometry>
    </collision>
  </link>
  <joint name="sink_area_footprint_joint" type="fixed">
    <origin rpy="0 0 3.141592653589793" xyz="1.855 1.3 0"/>
    <child link="sink_area_footprint"/>
    <parent link="room_link"/>
  </joint>
  <joint name="sink_area_main_joint" type="fixed">
    <origin rpy="0 0 0" xyz="0.29 1.03 0.41"/>
    <parent link="sink_area_footprint"/>
    <child link="sink_area"/>
  </joint>
  <link name="sink_area_surface">
    <inertial>
      <origin rpy="0 0 0" xyz="0.0 0.0 0.0"/>
      <mass value="1"/>
      <inertia ixx="1" ixy="0.0" ixz="0.0" iyy="1" iyz="0.0" izz="1"/>
    </inertial>
    <collision>
      <origin rpy="0 0 0" xyz="0 -0.225 0"/>
      <geometry>
        <box size="0.575 1.6 0.02"/>
      </geometry>
    </collision>
  </link>
  <joint name="sink_area_surface_joint" type="fixed">
    <origin rpy="0 0 0" xyz="0.0 0. 0.43"/>
    <parent link="sink_area"/>
    <child link="sink_area_surface"/>
  </joint>
  <link name="sink_area_sink">
    <inertial>
      <origin rpy="0 0 0" xyz="0.0 0.0 0.0"/>
      <mass value="1"/>
      <inertia ixx="1" ixy="0.0" ixz="0.0" iyy="1" iyz="0.0" izz="1"/>
    </inertial>
    <visual>
      <origin rpy="0 0 0" xyz="0 0 0"/>
      <geometry>
        <mesh filename="package://iai_kitchen/meshes/misc/Sink.dae"/>
      </geometry>
    </visual>
    <collision>
      <origin rpy="0 0 0" xyz="0 0 0"/>
      <geometry>
        <mesh filename="package://iai_kitchen/meshes/misc/Sink.obj"/>
      </geometry>
    </collision>
  </link>
  <joint name="sink_area_sink_joint" type="fixed">
    <origin rpy="0 0 0" xyz="0.005 0.47 0.4414"/>
    <parent link="sink_area"/>
    <child link="sink_area_sink"/>
  </joint>
  <link name="sink_area_right_panel">
    <inertial>
      <origin rpy="0 0 0" xyz="0.0 0.0 0.0"/>
      <mass value="1"/>
      <inertia ixx="1" ixy="0.0" ixz="0.0" iyy="1" iyz="0.0" izz="1"/>
    </inertial>
    <visual>
      <origin rpy="0 0 0" xyz="0 0 0"/>
      <geometry>
        <mesh filename="package://iai_kitchen/meshes/drawers/Panel_60.dae"/>
      </geometry>
    </visual>
    <collision>
      <origin rpy="0 0 0" xyz="0 0 0"/>
      <geometry>
        <mesh filename="package://iai_kitchen/meshes/drawers/Panel_60.obj"/>
      </geometry>
    </collision>
  </link>
  <joint name="sink_area_right_panel_joint" type="fixed">
    <origin rpy="0 0 0" xyz="0.28 0.7 0.355 "/>
    <parent link="sink_area"/>
    <child link="sink_area_right_panel"/>
  </joint>
  <link name="sink_area_trash_drawer_main">
    <inertial>
      <origin rpy="0 0 0" xyz="0.0 0.0 0.0"/>
      <mass value="1"/>
      <inertia ixx="1" ixy="0.0" ixz="0.0" iyy="1" iyz="0.0" izz="1"/>
    </inertial>
    <visual>
      <origin rpy="0 0 0" xyz="0 0 0"/>
      <geometry>
        <mesh filename="package://iai_kitchen/meshes/drawers/Drawer_60_58.dae"/>
      </geometry>
    </visual>
    <collision>
      <origin rpy="0 0 0" xyz="0 0 0"/>
      <geometry>
        <mesh filename="package://iai_kitchen/meshes/drawers/Drawer_60_58.obj"/>
      </geometry>
    </collision>
  </link>
  <link name="sink_area_trash_drawer_handle">
    <inertial>
      <origin rpy="0 0 0" xyz="0.0 0.0 0.0"/>
      <mass value="1"/>
      <inertia ixx="1" ixy="0.0" ixz="0.0" iyy="1" iyz="0.0" izz="1"/>
    </inertial>
    <visual>
      <origin rpy="0 0 0" xyz="0 0 0"/>
      <geometry>
        <mesh filename="package://iai_kitchen/meshes/handles/Handle60.dae"/>
      </geometry>
    </visual>
    <collision>
      <origin rpy="0 0 0" xyz="0 0 0"/>
      <geometry>
        <mesh filename="package://iai_kitchen/meshes/handles/Handle60.obj"/>
      </geometry>
    </collision>
  </link>
  <joint name="sink_area_trash_drawer_main_joint" type="prismatic">
    <origin rpy="0 0 0" xyz="0.01 0.7 -0.015 "/>
    <parent link="sink_area"/>
    <child link="sink_area_trash_drawer_main"/>
    <axis xyz="1. 0. 0.0"/>
    <limit effort="300" lower="0" upper="0.48" velocity="10"/>
    <!--
          <limit effort="300" lower="0" upper="0" velocity="10"/>
      -->
  </joint>
  <joint name="sink_area_trash_drawer_handle_joint" type="fixed">
    <origin rpy="0 0 0" xyz="0.37 0 0.25"/>
    <parent link="sink_area_trash_drawer_main"/>
    <child link="sink_area_trash_drawer_handle"/>
    <axis xyz="0 0 1"/>
    <limit effort="300" lower="0" upper="1.5707963267948966" velocity="10"/>
  </joint>
  <link name="sink_area_left_upper_drawer_main">
    <inertial>
      <origin rpy="0 0 0" xyz="0.0 0.0 0.0"/>
      <mass value="1"/>
      <inertia ixx="1" ixy="0.0" ixz="0.0" iyy="1" iyz="0.0" izz="1"/>
    </inertial>
    <visual>
      <origin rpy="0 0 0" xyz="0 0 0"/>
      <geometry>
        <mesh filename="package://iai_kitchen/meshes/drawers/Drawer_80_14.dae"/>
      </geometry>
    </visual>
    <collision>
      <origin rpy="0 0 0" xyz="0 0 0"/>
      <geometry>
        <mesh filename="package://iai_kitchen/meshes/drawers/Drawer_80_14.obj"/>
      </geometry>
    </collision>
  </link>
  <link name="sink_area_left_upper_drawer_handle">
    <inertial>
      <origin rpy="0 0 0" xyz="0.0 0.0 0.0"/>
      <mass value="1"/>
      <inertia ixx="1" ixy="0.0" ixz="0.0" iyy="1" iyz="0.0" izz="1"/>
    </inertial>
    <visual>
      <origin rpy="0 0 0" xyz="0 0 0"/>
      <geometry>
        <mesh filename="package://iai_kitchen/meshes/handles/Handle80.dae"/>
      </geometry>
    </visual>
    <collision>
      <origin rpy="0 0 0" xyz="0 0 0"/>
      <geometry>
        <mesh filename="package://iai_kitchen/meshes/handles/Handle80.obj"/>
      </geometry>
    </collision>
  </link>
  <joint name="sink_area_left_upper_drawer_main_joint" type="prismatic">
    <origin rpy="0 0 0" xyz="0.01 -0.6 0.345 "/>
    <parent link="sink_area"/>
    <child link="sink_area_left_upper_drawer_main"/>
    <axis xyz="1. 0. 0.0"/>
    <limit effort="300" lower="0" upper="0.48" velocity="10"/>
    <!--
          <limit effort="300" lower="0" upper="0" velocity="10"/>
      -->
  </joint>
  <joint name="sink_area_left_upper_drawer_handle_joint" type="fixed">
    <origin rpy="0 0 0" xyz="0.3525 0 0.0175"/>
    <parent link="sink_area_left_upper_drawer_main"/>
    <child link="sink_area_left_upper_drawer_handle"/>
    <axis xyz="0 0 1"/>
    <limit effort="300" lower="0" upper="1.5707963267948966" velocity="10"/>
  </joint>
  <link name="sink_area_left_middle_drawer_main">
    <inertial>
      <origin rpy="0 0 0" xyz="0.0 0.0 0.0"/>
      <mass value="1"/>
      <inertia ixx="1" ixy="0.0" ixz="0.0" iyy="1" iyz="0.0" izz="1"/>
    </inertial>
    <visual>
      <origin rpy="0 0 0" xyz="0 0 0"/>
      <geometry>
        <mesh filename="package://iai_kitchen/meshes/drawers/Drawer_80_29.dae"/>
      </geometry>
    </visual>
    <collision>
      <origin rpy="0 0 0" xyz="0 0 0"/>
      <geometry>
        <mesh filename="package://iai_kitchen/meshes/drawers/Drawer_80_29.obj"/>
      </geometry>
    </collision>
  </link>
  <link name="sink_area_left_middle_drawer_handle">
    <inertial>
      <origin rpy="0 0 0" xyz="0.0 0.0 0.0"/>
      <mass value="1"/>
      <inertia ixx="1" ixy="0.0" ixz="0.0" iyy="1" iyz="0.0" izz="1"/>
    </inertial>
    <visual>
      <origin rpy="0 0 0" xyz="0 0 0"/>
      <geometry>
        <mesh filename="package://iai_kitchen/meshes/handles/Handle80.dae"/>
      </geometry>
    </visual>
    <collision>
      <origin rpy="0 0 0" xyz="0 0 0"/>
      <geometry>
        <mesh filename="package://iai_kitchen/meshes/handles/Handle80.obj"/>
      </geometry>
    </collision>
  </link>
  <joint name="sink_area_left_middle_drawer_main_joint" type="prismatic">
    <origin rpy="0 0 0" xyz="0.01 -0.6 0.12 "/>
    <parent link="sink_area"/>
    <child link="sink_area_left_middle_drawer_main"/>
    <axis xyz="1. 0. 0.0"/>
    <limit effort="300" lower="0" upper="0.48" velocity="10"/>
    <!--
          <limit effort="300" lower="0" upper="0" velocity="10"/>
      -->
  </joint>
  <joint name="sink_area_left_middle_drawer_handle_joint" type="fixed">
    <origin rpy="0 0 0" xyz="0.3525 0 0.11"/>
    <parent link="sink_area_left_middle_drawer_main"/>
    <child link="sink_area_left_middle_drawer_handle"/>
    <axis xyz="0 0 1"/>
    <limit effort="300" lower="0" upper="1.5707963267948966" velocity="10"/>
  </joint>
  <link name="sink_area_left_bottom_drawer_main">
    <inertial>
      <origin rpy="0 0 0" xyz="0.0 0.0 0.0"/>
      <mass value="1"/>
      <inertia ixx="1" ixy="0.0" ixz="0.0" iyy="1" iyz="0.0" izz="1"/>
    </inertial>
    <visual>
      <origin rpy="0 0 0" xyz="0 0 0"/>
      <geometry>
        <mesh filename="package://iai_kitchen/meshes/drawers/Drawer_80_29.dae"/>
      </geometry>
    </visual>
    <collision>
      <origin rpy="0 0 0" xyz="0 0 0"/>
      <geometry>
        <mesh filename="package://iai_kitchen/meshes/drawers/Drawer_80_29.obj"/>
      </geometry>
    </collision>
  </link>
  <link name="sink_area_left_bottom_drawer_handle">
    <inertial>
      <origin rpy="0 0 0" xyz="0.0 0.0 0.0"/>
      <mass value="1"/>
      <inertia ixx="1" ixy="0.0" ixz="0.0" iyy="1" iyz="0.0" izz="1"/>
    </inertial>
    <visual>
      <origin rpy="0 0 0" xyz="0 0 0"/>
      <geometry>
        <mesh filename="package://iai_kitchen/meshes/handles/Handle80.dae"/>
      </geometry>
    </visual>
    <collision>
      <origin rpy="0 0 0" xyz="0 0 0"/>
      <geometry>
        <mesh filename="package://iai_kitchen/meshes/handles/Handle80.obj"/>
      </geometry>
    </collision>
  </link>
  <joint name="sink_area_left_bottom_drawer_main_joint" type="prismatic">
    <origin rpy="0 0 0" xyz="0.01 -0.6 -0.18"/>
    <parent link="sink_area"/>
    <child link="sink_area_left_bottom_drawer_main"/>
    <axis xyz="1. 0. 0.0"/>
    <limit effort="300" lower="0" upper="0.48" velocity="10"/>
    <!--
          <limit effort="300" lower="0" upper="0" velocity="10"/>
      -->
  </joint>
  <joint name="sink_area_left_bottom_drawer_handle_joint" type="fixed">
    <origin rpy="0 0 0" xyz="0.3525 0 0.11"/>
    <parent link="sink_area_left_bottom_drawer_main"/>
    <child link="sink_area_left_bottom_drawer_handle"/>
    <axis xyz="0 0 1"/>
    <limit effort="300" lower="0" upper="1.5707963267948966" velocity="10"/>
  </joint>
  <link name="sink_area_dish_washer_main">
    <inertial>
      <origin rpy="0 0 0" xyz="0.0 0.0 0.0"/>
      <mass value="1"/>
      <inertia ixx="1" ixy="0.0" ixz="0.0" iyy="1" iyz="0.0" izz="1"/>
    </inertial>
    <visual>
      <origin rpy="0 0 0" xyz="0 0 0"/>
      <geometry>
        <mesh filename="package://iai_kitchen/meshes/misc/DishWasher.dae"/>
      </geometry>
    </visual>
    <collision>
      <origin rpy="0 0 0" xyz="0 0 0"/>
      <geometry>
        <mesh filename="package://iai_kitchen/meshes/misc/DishWasher.obj"/>
      </geometry>
    </collision>
  </link>
  <link name="sink_area_dish_washer_door">
    <inertial>
      <origin rpy="0 0 0" xyz="0.0 0.0 0.0"/>
      <mass value="1"/>
      <inertia ixx="1" ixy="0.0" ixz="0.0" iyy="1" iyz="0.0" izz="1"/>
    </inertial>
    <visual>
      <origin rpy="1.5707963267948966 0 0" xyz="0 0.055 0"/>
      <geometry>
        <mesh filename="package://iai_kitchen/meshes/misc/DishWasherDoor.dae"/>
      </geometry>
    </visual>
    <collision>
      <origin rpy="1.5707963267948966 0 0" xyz="0 0.055 0"/>
      <geometry>
        <mesh filename="package://iai_kitchen/meshes/misc/DishWasherDoor.obj"/>
      </geometry>
    </collision>
  </link>
  <link name="sink_area_dish_washer_door_handle">
    <inertial>
      <origin rpy="0 0 0" xyz="0.0 0.0 0.0"/>
      <mass value="1"/>
      <inertia ixx="1" ixy="0.0" ixz="0.0" iyy="1" iyz="0.0" izz="1"/>
    </inertial>
    <visual>
      <origin rpy="0 0 0" xyz="0 0 0"/>
      <geometry>
        <mesh filename="package://iai_kitchen/meshes/handles/Handle60.dae"/>
      </geometry>
    </visual>
    <collision>
      <origin rpy="0 0 0" xyz="0 0 0"/>
      <geometry>
        <mesh filename="package://iai_kitchen/meshes/handles/Handle60.obj"/>
      </geometry>
    </collision>
  </link>
  <!--
    <xacro:if value="simulated"/>
    -->
  <joint name="sink_area_dish_washer_main_joint" type="fixed">
    <origin rpy="0 0 0" xyz="0.01 0.1 0.06"/>
    <parent link="sink_area"/>
    <child link="sink_area_dish_washer_main"/>
  </joint>
  <!--
    <xacro:if value="${simulated}">
    <joint name="${name}_door_joint" type="revolute">
      <origin xyz="0.27 0. -0.325" rpy="${-0.5*pi} 0 0" />
      <parent link="${name}_main"/>
      <child link="${name}_door"/>
      <axis xyz="0 0 1"/>
       FIXME make closed position stable instead of forbidding opening...
      <limit lower="0" upper="0" effort="300" velocity="10"/>
    </joint>

    </xacro:if>
    -->
  <!--
    <xacro:unless value="${simulated}">
    -->
  <joint name="sink_area_dish_washer_door_joint" type="revolute">
    <origin rpy="-1.5707963267948966 0 0" xyz="0.27 0. -0.285"/>
    <parent link="sink_area_dish_washer_main"/>
    <child link="sink_area_dish_washer_door"/>
    <axis xyz="0 0 1"/>
    <!--
      <limit lower="0" upper="${0.5*pi}" effort="300" velocity="10"/>
      -->
    <limit effort="300" lower="0" upper="1.5707963267948966" velocity="10"/>
  </joint>
  <!--
    </xacro:unless>
  -->
  <joint name="sink_area_dish_washer_door_handle_joint" type="fixed">
    <origin rpy="-1.5707963267948966 0 0" xyz="0.085 -0.575 0.0"/>
    <parent link="sink_area_dish_washer_door"/>
    <child link="sink_area_dish_washer_door_handle"/>
  </joint>
  <joint name="sink_area_dish_washer_tray_main" type="prismatic">
    <origin xyz="-0.08 0 0.15"/>
    <parent link="sink_area_dish_washer_main"/>
    <child link="sink_area_dish_washer_tray_bottom"/>
    <axis xyz="1 0 0"/>
    <limit effort="300" lower="0" upper="0.48" velocity="10"/>
  </joint>
  <link name="sink_area_dish_washer_tray_bottom">
    <visual>
      <geometry>
        <box size="0.32 0.5 0.05"/>
      </geometry>
    </visual>
    <collision>
      <geometry>
        <box size="0.32 0.5 0.05"/>
      </geometry>
    </collision>
  </link>
  <link name="sink_area_dish_washer_tray_left_side">
    <visual>
      <geometry>
        <box size="0.32 0.005 0.17"/>
      </geometry>
    </visual>
    <collision>
      <geometry>
        <box size="0.32 0.005 0.17"/>
      </geometry>
    </collision>
  </link>
  <link name="sink_area_dish_washer_tray_right_side">
    <visual>
      <geometry>
        <box size="0.32 0.005 0.17"/>
      </geometry>
    </visual>
    <collision>
      <geometry>
        <box size="0.32 0.005 0.17"/>
      </geometry>
    </collision>
  </link>
  <link name="sink_area_dish_washer_tray_back_side">
    <visual>
      <geometry>
        <box size="0.005 0.5 0.17"/>
      </geometry>
    </visual>
    <collision>
      <geometry>
        <box size="0.005 0.5 0.17"/>
      </geometry>
    </collision>
  </link>
  <link name="sink_area_dish_washer_tray_front_side">
    <visual>
      <geometry>
        <box size="0.005 0.5 0.17"/>
      </geometry>
    </visual>
    <collision>
      <geometry>
        <box size="0.005 0.5 0.17"/>
      </geometry>
    </collision>
  </link>
  <joint name="sink_area_dish_washer_tray_bottom_left" type="fixed">
    <origin xyz="-0.0 -0.25 0.075"/>
    <child link="sink_area_dish_washer_tray_left_side"/>
    <parent link="sink_area_dish_washer_tray_bottom"/>
  </joint>
  <joint name="sink_area_dish_washer_tray_bottom_right" type="fixed">
    <origin xyz="-0.0 0.25 0.075"/>
    <child link="sink_area_dish_washer_tray_right_side"/>
    <parent link="sink_area_dish_washer_tray_bottom"/>
  </joint>
  <joint name="sink_area_dish_washer_tray_bottom_back" type="fixed">
    <origin xyz="-0.16 0 0.075"/>
    <child link="sink_area_dish_washer_tray_back_side"/>
    <parent link="sink_area_dish_washer_tray_bottom"/>
  </joint>
  <joint name="sink_area_dish_washer_tray_bottom_front" type="fixed">
    <origin xyz="0.16 0 0.075"/>
    <child link="sink_area_dish_washer_tray_front_side"/>
    <parent link="sink_area_dish_washer_tray_bottom"/>
  </joint>
  <joint name="sink_area_dish_washer_tray_handle_joint" type="fixed">
    <origin xyz="0.06 -0.1 -0.02"/>
    <child link="sink_area_dish_washer_tray_handle_front_side"/>
    <parent link="sink_area_dish_washer_tray_front_side"/>
  </joint>
  <link name="sink_area_dish_washer_tray_handle_left_side">
    <visual>
      <geometry>
        <box size="0.03 0.01 0.01"/>
      </geometry>
    </visual>
    <collision>
      <geometry>
        <box size="0.03 0.01 0.01"/>
      </geometry>
    </collision>
  </link>
  <link name="sink_area_dish_washer_tray_handle_right_side">
    <visual>
      <geometry>
        <box size="0.03 0.01 0.01"/>
      </geometry>
    </visual>
    <collision>
      <geometry>
        <box size="0.03 0.01 0.01"/>
      </geometry>
    </collision>
  </link>
  <link name="sink_area_dish_washer_tray_handle_front_side">
    <visual>
      <geometry>
        <box size="0.01 0.2 0.01"/>
      </geometry>
    </visual>
    <collision>
      <geometry>
        <box size="0.01 0.2 0.01"/>
      </geometry>
    </collision>
  </link>
  <joint name="sink_area_dish_washer_tray_handle_front_left_joint" type="fixed">
    <origin xyz="-0.01 -0.1 0"/>
    <child link="sink_area_dish_washer_tray_handle_left_side"/>
    <parent link="sink_area_dish_washer_tray_handle_front_side"/>
  </joint>
  <joint name="sink_area_dish_washer_tray_handle_front_right_joint" type="fixed">
    <origin xyz="-0.01 0.1 0"/>
    <child link="sink_area_dish_washer_tray_handle_right_side"/>
    <parent link="sink_area_dish_washer_tray_handle_front_side"/>
  </joint>
  <link name="table_area_main">
    <inertial>
      <origin rpy="0 0 0" xyz="0.0 0.0 0.0"/>
      <mass value="1"/>
      <inertia ixx="1" ixy="0.0" ixz="0.0" iyy="1" iyz="0.0" izz="1"/>
    </inertial>
    <visual>
      <origin rpy="0 0 0" xyz="0 0 0.3619"/>
      <geometry>
        <mesh filename="package://iai_kitchen/meshes/misc/big_table_1.dae"/>
      </geometry>
    </visual>
    <collision>
      <origin rpy="0 0 0" xyz="0 0 0.3619"/>
      <geometry>
        <mesh filename="package://iai_kitchen/meshes/misc/big_table_1.obj"/>
      </geometry>
    </collision>
  </link>
  <joint name="table_area_main_joint" type="fixed">
    <origin rpy="0 0 3.141592653589793" xyz="-2.4 -1.5 0"/>
    <parent link="room_link"/>
    <child link="table_area_main"/>
  </joint>
  <gazebo>
    <static>false</static>
  </gazebo>
</robot>

